order-book/a1-a2-testcases/hard-exec-cancel-race.in

    # Adds a pair of matchable concurrent orders, cancels them immediately
    # So the exec may or may not happen depending on if the cancels happen first
    
40
o
0 B 0 INST0 2700 1
0 C 0
20 S 1 INST0 2700 1
20 C 1
0 w 1
20 w 0
1 B 2 INST1 2700 1
1 C 2
21 S 3 INST1 2700 1
21 C 3
1 w 3
21 w 2
2 B 4 INST2 2700 1
2 C 4
22 S 5 INST2 2700 1
22 C 5
2 w 5
22 w 4
3 B 6 INST3 2700 1
3 C 6
23 S 7 INST3 2700 1
23 C 7
3 w 7
23 w 6
4 B 8 INST4 2700 1
4 C 8
24 S 9 INST4 2700 1
24 C 9
4 w 9
24 w 8
5 B 10 INST5 2700 1
5 C 10
25 S 11 INST5 2700 1
25 C 11
5 w 11
25 w 10
6 B 12 INST6 2700 1
6 C 12
26 S 13 INST6 2700 1
26 C 13
6 w 13
26 w 12
7 B 14 INST7 2700 1
7 C 14
27 S 15 INST7 2700 1
27 C 15
7 w 15
27 w 14
8 B 16 INST8 2700 1
8 C 16
28 S 17 INST8 2700 1
28 C 17
8 w 17
28 w 16
9 B 18 INST9 2700 1
9 C 18
29 S 19 INST9 2700 1
29 C 19
9 w 19
29 w 18
10 B 20 INST10 2700 1
10 C 20
30 S 21 INST10 2700 1
30 C 21
10 w 21
30 w 20
11 B 22 INST11 2700 1
11 C 22
31 S 23 INST11 2700 1
31 C 23
11 w 23
31 w 22
12 B 24 INST12 2700 1
12 C 24
32 S 25 INST12 2700 1
32 C 25
12 w 25
32 w 24
13 B 26 INST13 2700 1
13 C 26
33 S 27 INST13 2700 1
33 C 27
13 w 27
33 w 26
14 B 28 INST14 2700 1
14 C 28
34 S 29 INST14 2700 1
34 C 29
14 w 29
34 w 28
15 B 30 INST15 2700 1
15 C 30
35 S 31 INST15 2700 1
35 C 31
15 w 31
35 w 30
16 B 32 INST16 2700 1
16 C 32
36 S 33 INST16 2700 1
36 C 33
16 w 33
36 w 32
17 B 34 INST17 2700 1
17 C 34
37 S 35 INST17 2700 1
37 C 35
17 w 35
37 w 34
18 B 36 INST18 2700 1
18 C 36
38 S 37 INST18 2700 1
38 C 37
18 w 37
38 w 36
19 B 38 INST19 2700 1
19 C 38
39 S 39 INST19 2700 1
39 C 39
19 w 39
39 w 38
0 B 40 INST0 2700 1
0 C 40
20 S 41 INST0 2700 1
20 C 41
0 w 41
20 w 40
1 B 42 INST1 2700 1
1 C 42
21 S 43 INST1 2700 1
21 C 43
1 w 43
21 w 42
2 B 44 INST2 2700 1
2 C 44
22 S 45 INST2 2700 1
22 C 45
2 w 45
22 w 44
3 B 46 INST3 2700 1
3 C 46
23 S 47 INST3 2700 1
23 C 47
3 w 47
23 w 46
4 B 48 INST4 2700 1
4 C 48
24 S 49 INST4 2700 1
24 C 49
4 w 49
24 w 48
5 B 50 INST5 2700 1
5 C 50
25 S 51 INST5 2700 1
25 C 51
5 w 51
25 w 50
6 B 52 INST6 2700 1
6 C 52
26 S 53 INST6 2700 1
26 C 53
6 w 53
26 w 52
7 B 54 INST7 2700 1
7 C 54
27 S 55 INST7 2700 1
27 C 55
7 w 55
27 w 54
8 B 56 INST8 2700 1
8 C 56
28 S 57 INST8 2700 1
28 C 57
8 w 57
28 w 56
9 B 58 INST9 2700 1
9 C 58
29 S 59 INST9 2700 1
29 C 59
9 w 59
29 w 58
10 B 60 INST10 2700 1
10 C 60
30 S 61 INST10 2700 1
30 C 61
10 w 61
30 w 60
11 B 62 INST11 2700 1
11 C 62
31 S 63 INST11 2700 1
31 C 63
11 w 63
31 w 62
12 B 64 INST12 2700 1
12 C 64
32 S 65 INST12 2700 1
32 C 65
12 w 65
32 w 64
13 B 66 INST13 2700 1
13 C 66
33 S 67 INST13 2700 1
33 C 67
13 w 67
33 w 66
14 B 68 INST14 2700 1
14 C 68
34 S 69 INST14 2700 1
34 C 69
14 w 69
34 w 68
15 B 70 INST15 2700 1
15 C 70
35 S 71 INST15 2700 1
35 C 71
15 w 71
35 w 70
16 B 72 INST16 2700 1
16 C 72
36 S 73 INST16 2700 1
36 C 73
16 w 73
36 w 72
17 B 74 INST17 2700 1
17 C 74
37 S 75 INST17 2700 1
37 C 75
17 w 75
37 w 74
18 B 76 INST18 2700 1
18 C 76
38 S 77 INST18 2700 1
38 C 77
18 w 77
38 w 76
19 B 78 INST19 2700 1
19 C 78
39 S 79 INST19 2700 1
39 C 79
19 w 79
39 w 78
0 B 80 INST0 2700 1
0 C 80
20 S 81 INST0 2700 1
20 C 81
0 w 81
20 w 80
1 B 82 INST1 2700 1
1 C 82
21 S 83 INST1 2700 1
21 C 83
1 w 83
21 w 82
2 B 84 INST2 2700 1
2 C 84
22 S 85 INST2 2700 1
22 C 85
2 w 85
22 w 84
3 B 86 INST3 2700 1
3 C 86
23 S 87 INST3 2700 1
23 C 87
3 w 87
23 w 86
4 B 88 INST4 2700 1
4 C 88
24 S 89 INST4 2700 1
24 C 89
4 w 89
24 w 88
5 B 90 INST5 2700 1
5 C 90
25 S 91 INST5 2700 1
25 C 91
5 w 91
25 w 90
6 B 92 INST6 2700 1
6 C 92
26 S 93 INST6 2700 1
26 C 93
6 w 93
26 w 92
7 B 94 INST7 2700 1
7 C 94
27 S 95 INST7 2700 1
27 C 95
7 w 95
27 w 94
8 B 96 INST8 2700 1
8 C 96
28 S 97 INST8 2700 1
28 C 97
8 w 97
28 w 96
9 B 98 INST9 2700 1
9 C 98
29 S 99 INST9 2700 1
29 C 99
9 w 99
29 w 98
10 B 100 INST10 2700 1
10 C 100
30 S 101 INST10 2700 1
30 C 101
10 w 101
30 w 100
11 B 102 INST11 2700 1
11 C 102
31 S 103 INST11 2700 1
31 C 103
11 w 103
31 w 102
12 B 104 INST12 2700 1
12 C 104
32 S 105 INST12 2700 1
32 C 105
12 w 105
32 w 104
13 B 106 INST13 2700 1
13 C 106
33 S 107 INST13 2700 1
33 C 107
13 w 107
33 w 106
14 B 108 INST14 2700 1
14 C 108
34 S 109 INST14 2700 1
34 C 109
14 w 109
34 w 108
15 B 110 INST15 2700 1
15 C 110
35 S 111 INST15 2700 1
35 C 111
15 w 111
35 w 110
16 B 112 INST16 2700 1
16 C 112
36 S 113 INST16 2700 1
36 C 113
16 w 113
36 w 112
17 B 114 INST17 2700 1
17 C 114
37 S 115 INST17 2700 1
37 C 115
17 w 115
37 w 114
18 B 116 INST18 2700 1
18 C 116
38 S 117 INST18 2700 1
38 C 117
18 w 117
38 w 116
19 B 118 INST19 2700 1
19 C 118
39 S 119 INST19 2700 1
39 C 119
19 w 119
39 w 118
0 B 120 INST0 2700 1
0 C 120
20 S 121 INST0 2700 1
20 C 121
0 w 121
20 w 120
1 B 122 INST1 2700 1
1 C 122
21 S 123 INST1 2700 1
21 C 123
1 w 123
21 w 122
2 B 124 INST2 2700 1
2 C 124
22 S 125 INST2 2700 1
22 C 125
2 w 125
22 w 124
3 B 126 INST3 2700 1
3 C 126
23 S 127 INST3 2700 1
23 C 127
3 w 127
23 w 126
4 B 128 INST4 2700 1
4 C 128
24 S 129 INST4 2700 1
24 C 129
4 w 129
24 w 128
5 B 130 INST5 2700 1
5 C 130
25 S 131 INST5 2700 1
25 C 131
5 w 131
25 w 130
6 B 132 INST6 2700 1
6 C 132
26 S 133 INST6 2700 1
26 C 133
6 w 133
26 w 132
7 B 134 INST7 2700 1
7 C 134
27 S 135 INST7 2700 1
27 C 135
7 w 135
27 w 134
8 B 136 INST8 2700 1
8 C 136
28 S 137 INST8 2700 1
28 C 137
8 w 137
28 w 136
9 B 138 INST9 2700 1
9 C 138
29 S 139 INST9 2700 1
29 C 139
9 w 139
29 w 138
10 B 140 INST10 2700 1
10 C 140
30 S 141 INST10 2700 1
30 C 141
10 w 141
30 w 140
11 B 142 INST11 2700 1
11 C 142
31 S 143 INST11 2700 1
31 C 143
11 w 143
31 w 142
12 B 144 INST12 2700 1
12 C 144
32 S 145 INST12 2700 1
32 C 145
12 w 145
32 w 144
13 B 146 INST13 2700 1
13 C 146
33 S 147 INST13 2700 1
33 C 147
13 w 147
33 w 146
14 B 148 INST14 2700 1
14 C 148
34 S 149 INST14 2700 1
34 C 149
14 w 149
34 w 148
15 B 150 INST15 2700 1
15 C 150
35 S 151 INST15 2700 1
35 C 151
15 w 151
35 w 150
16 B 152 INST16 2700 1
16 C 152
36 S 153 INST16 2700 1
36 C 153
16 w 153
36 w 152
17 B 154 INST17 2700 1
17 C 154
37 S 155 INST17 2700 1
37 C 155
17 w 155
37 w 154
18 B 156 INST18 2700 1
18 C 156
38 S 157 INST18 2700 1
38 C 157
18 w 157
38 w 156
19 B 158 INST19 2700 1
19 C 158
39 S 159 INST19 2700 1
39 C 159
19 w 159
39 w 158
0 B 160 INST0 2700 1
0 C 160
20 S 161 INST0 2700 1
20 C 161
0 w 161
20 w 160
1 B 162 INST1 2700 1
1 C 162
21 S 163 INST1 2700 1
21 C 163
1 w 163
21 w 162
2 B 164 INST2 2700 1
2 C 164
22 S 165 INST2 2700 1
22 C 165
2 w 165
22 w 164
3 B 166 INST3 2700 1
3 C 166
23 S 167 INST3 2700 1
23 C 167
3 w 167
23 w 166
4 B 168 INST4 2700 1
4 C 168
24 S 169 INST4 2700 1
24 C 169
4 w 169
24 w 168
5 B 170 INST5 2700 1
5 C 170
25 S 171 INST5 2700 1
25 C 171
5 w 171
25 w 170
6 B 172 INST6 2700 1
6 C 172
26 S 173 INST6 2700 1
26 C 173
6 w 173
26 w 172
7 B 174 INST7 2700 1
7 C 174
27 S 175 INST7 2700 1
27 C 175
7 w 175
27 w 174
8 B 176 INST8 2700 1
8 C 176
28 S 177 INST8 2700 1
28 C 177
8 w 177
28 w 176
9 B 178 INST9 2700 1
9 C 178
29 S 179 INST9 2700 1
29 C 179
9 w 179
29 w 178
10 B 180 INST10 2700 1
10 C 180
30 S 181 INST10 2700 1
30 C 181
10 w 181
30 w 180
11 B 182 INST11 2700 1
11 C 182
31 S 183 INST11 2700 1
31 C 183
11 w 183
31 w 182
12 B 184 INST12 2700 1
12 C 184
32 S 185 INST12 2700 1
32 C 185
12 w 185
32 w 184
13 B 186 INST13 2700 1
13 C 186
33 S 187 INST13 2700 1
33 C 187
13 w 187
33 w 186
14 B 188 INST14 2700 1
14 C 188
34 S 189 INST14 2700 1
34 C 189
14 w 189
34 w 188
15 B 190 INST15 2700 1
15 C 190
35 S 191 INST15 2700 1
35 C 191
15 w 191
35 w 190
16 B 192 INST16 2700 1
16 C 192
36 S 193 INST16 2700 1
36 C 193
16 w 193
36 w 192
17 B 194 INST17 2700 1
17 C 194
37 S 195 INST17 2700 1
37 C 195
17 w 195
37 w 194
18 B 196 INST18 2700 1
18 C 196
38 S 197 INST18 2700 1
38 C 197
18 w 197
38 w 196
19 B 198 INST19 2700 1
19 C 198
39 S 199 INST19 2700 1
39 C 199
19 w 199
39 w 198
0 B 200 INST0 2700 1
0 C 200
20 S 201 INST0 2700 1
20 C 201
0 w 201
20 w 200
1 B 202 INST1 2700 1
1 C 202
21 S 203 INST1 2700 1
21 C 203
1 w 203
21 w 202
2 B 204 INST2 2700 1
2 C 204
22 S 205 INST2 2700 1
22 C 205
